Workbook

Sheet Tutorial
B2: Tutorial de como usar essa planilha
B4: 1- Na parte inferior existem opções de aba para se escolher que indicam o tipo de produto que vai ser inserido no sistema
B5: por enquanto existem os tipos DOCES (Lacta, Suflair, etc), SALGADINHOS (Torcida, Doritos, etc), BEBIDAS (Guaraná, Coca, etc),
B6: então você escolhe a aba do tipo de produto de acordo com o tipo que o produto desejado mais se encaixa.
B34: 2- Dentro da aba vai existir uma tabela desse tipo, nela é possível inserir o nome do produto, o preço de compra (quanto custou para comprar o produto), preço unitário (valor que vai ser vendido o produto),
B35: Nº de fardos (quantidade de fardos comprados, se existir), Qtd por fardo (quantidade de produtos por fardo, se existir), quantidade total (número total de produtos),
B36: estoque mínimo (quantidade mínima que se deve ter do produto, se quiser informar)
B69: 3- E é isso!! De resto temos uma aba "CONSOLIDADO" que é onde vai ficar a tabela com todas as informações dessas outras abas.

Sheet Doces
A1: IMPORTAÇÃO DE PRODUTOS - DOCES
A2: Preencha os dados abaixo. Campos opcionais podem ficar em branco. | J2: Exemplo
A3: Nome do Produto | B3: Preço de compra (R$) | C3: Preço Unitário (R$) | D3: Nº de Fardos (Opcional) | E3: Qtd por Fardo (Opcional) | F3: Quantidade Total | G3: Estoque Mínimo (Opcional) | J3: Nome do Produto | K3: Preço de compra (R$) | L3: Preço Unitário (R$) | M3: Nº de Fardos (Opcional) | N3: Qtd por Fardo (Opcional) | O3: Quantidade Total | P3: Estoque Mínimo (Opcional)
F4: =D4*E4 -> 0 | J4: Chocolate Garoto | K4: 1 | L4: 2.5 | O4: 70 | P4: 50
F5: =D5*E5 -> 0 | J5: Bala 7 Belo | K5: 80 | L5: 0.5 | M5: 10 | N5: 50 | O5: =M5*N5 -> 500 | P5: 100
F6: =D6*E6 -> 0 | J6: Pirulito Chup-Chup | K6: 0.5 | L6: 1 | O6: 70 | P6: 30
F7: =D7*E7 -> 0
F8: =D8*E8 -> 0 | J8: OBS: Para compras em quantidades de fardos é possível inserir o preço do fardo direto, só informar a quantidade de fardos
F9: =D9*E9 -> 0 | J9: OBS: É possível também inserir o preço de compra de cada unidade, nesse caso não se informa o número de fardos, e só a quantidade total
F10: =D10*E10 -> 0 | J10: OBS: Pelo sistema usamos uma lógica de estoque mínimo, esse número indica uma quantidade mínima que deve ter de um produto, depois disso é criado um alerta para comprar mais desse produto
F11: =D11*E11 -> 0
F12: =D12*E12 -> 0
F13: =D13*E13 -> 0
F14: =D14*E14 -> 0
F15: =D15*E15 -> 0
F16: =D16*E16 -> 0
F17: =D17*E17 -> 0
F18: =D18*E18 -> 0
F19: =D19*E19 -> 0
F20: =D20*E20 -> 0
F21: =D21*E21 -> 0
F22: =D22*E22 -> 0
... F26: =D26*E26 -> 0
A28: 💡 IMPORTANTE: Quantidade Total = Nº de Fardos × Qtd por Fardo (calculado automaticamente se informar ambos)

Sheet Salgados
A1: IMPORTAÇÃO DE PRODUTOS - SALGADOS
A2: Preencha os dados abaixo. Campos opcionais podem ficar em branco. | I2: Exemplo
A3: Nome do Produto | B3: Preço de compra (R$) | C3: Preço Unitário (R$) | D3: Nº de Fardos (Opcional) | E3: Qtd por Fardo (Opcional) | F3: Quantidade Total | G3: Estoque Mínimo (Opcional) | I3: Nome do Produto | J3: Preço de compra (R$) | K3: Preço Unitário (R$) | L3: Nº de Fardos (Opcional) | M3: Qtd por Fardo (Opcional) | N3: Quantidade Total | O3: Estoque Mínimo (Opcional)
E4: =C4*D4 -> 0 | I4: Cheetos | J4: 1 | K4: 2.5 | N4: 50 | O4: 50
E5: =C5*D5 -> 0 | I5: Pringles | J5: 80 | K5: 0.5 | L5: 10 | M5: 50 | N5: =L5*M5 -> 500 | O5: 100
E6: =C6*D6 -> 0 | I6: Torcida | J6: 0.5 | K6: 1 | N6: 20 | O6: 30
E7: =C7*D7 -> 0 | F7: =IF(AND(D7<>"",E7<>""),D7*E7,"") | I7: Doritos | J7: 90 | K7: 10 | L7: 10 | M7: =IF(AND(K7<>"",L7<>""),K7*L7,"") -> 100 | N7: 1000 | O7: 10
E8: =C8*D8 -> 0 | F8: =IF(AND(D8<>"",E8<>""),D8*E8,"")
E9: =C9*D9 -> 0 | F9: =IF(AND(D9<>"",E9<>""),D9*E9,"") | I9: OBS: Para compras em quantidades de fardos é possível inserir o preço do fardo direto, só informar a quantidade de fardos
E10: =C10*D10 -> 0 | F10: =IF(AND(D10<>"",E10<>""),D10*E10,"") | I10: OBS: É possível também inserir o preço de compra de cada unidade, nesse caso não se informa o número de fardos, e só a quantidade total
E11: =C11*D11 -> 0 | F11: =IF(AND(D11<>"",E11<>""),D11*E11,"") | I11: OBS: Pelo sistema usamos uma lógica de estoque mínimo, esse número indica uma quantidade mínima que deve ter de um produto, depois disso é criado um alerta para comprar mais desse produto
E12: =C12*D12 -> 0 | F12: =IF(AND(D12<>"",E12<>""),D12*E12,"")
E13: =C13*D13 -> 0 | F13: =IF(AND(D13<>"",E13<>""),D13*E13,"")
E14: =C14*D14 -> 0 | F14: =IF(AND(D14<>"",E14<>""),D14*E14,"")
E15: =C15*D15 -> 0 | F15: =IF(AND(D15<>"",E15<>""),D15*E15,"")
E16: =C16*D16 -> 0 | F16: =IF(AND(D16<>"",E16<>""),D16*E16,"")
E17: =C17*D17 -> 0 | F17: =IF(AND(D17<>"",E17<>""),D17*E17,"")
E18: =C18*D18 -> 0 | F18: =IF(AND(D18<>"",E18<>""),D18*E18,"")
E19: =C19*D19 -> 0 | F19: =IF(AND(D19<>"",E19<>""),D19*E19,"")
E20: =C20*D20 -> 0 | F20: =IF(AND(D20<>"",E20<>""),D20*E20,"")
E21: =C21*D21 -> 0 | F21: =IF(AND(D21<>"",E21<>""),D21*E21,"")
E22: =C22*D22 -> 0 | F22: =IF(AND(D22<>"",E22<>""),D22*E22,"")
E23: =C23*D23 -> 0 | F23: =IF(AND(D23<>"",E23<>""),D23*E23,"")
... E26: =C26*D26 -> 0 | F26: =IF(AND(D26<>"",E26<>""),D26*E26,"")
A28: 💡 IMPORTANTE: Quantidade Total = Nº de Fardos × Qtd por Fardo (calculado automaticamente se informar ambos)

Sheet Bebidas
A1: IMPORTAÇÃO DE PRODUTOS - BEBIDAS
A2: Preencha os dados abaixo. Campos opcionais podem ficar em branco. | J2: Exemplo
A3: Nome do Produto | B3: Preço de compra (R$) | C3: Preço Unitário (R$) | D3: Nº de Fardos (Opcional) | E3: Qtd por Fardo (Opcional) | F3: Quantidade Total | G3: Estoque Mínimo (Opcional) | J3: Nome do Produto | K3: Preço de compra (R$) | L3: Preço Unitário (R$) | M3: Nº de Fardos (Opcional) | N3: Qtd por Fardo (Opcional) | O3: Quantidade Total | P3: Estoque Mínimo (Opcional)
F4: =D4*E4 -> 0 | J4: Coca-Cola 2L | K4: 80 | L4: 8 | M4: 6 | N4: 6 | O4: 36 | P4: 20
F5: =D5*E5 -> 0 | J5: Água Mineral 500ml | K5: 60 | L5: 2 | M5: 12 | N5: 12 | O5: =M5*N5 -> 144 | P5: 50
F6: =D6*E6 -> 0 | J6: Suco Del Valle | K6: 0.5 | L6: 3.5 | O6: 60 | P6: 30
F7: =D7*E7 -> 0 | J7: Coca-Cola zero | K7: 5 | L7: 4 | O7: 70 | P7: 10
F8: =D8*E8 -> 0
F9: =D9*E9 -> 0 | J9: OBS: Para compras em quantidades de fardos é possível inserir o preço do fardo direto, só informar a quantidade de fardos
F10: =D10*E10 -> 0 | J10: OBS: É possível também inserir o preço de compra de cada unidade, nesse caso não se informa o número de fardos, e só a quantidade total
F11: =D11*E11 -> 0 | J11: OBS: Pelo sistema usamos uma lógica de estoque mínimo, esse número indica uma quantidade mínima que deve ter de um produto, depois disso é criado um alerta para comprar mais desse produto
F12: =D12*E12 -> 0
F13: =D13*E13 -> 0
F14: =D14*E14 -> 0
F15: =D15*E15 -> 0
F16: =D16*E16 -> 0
F17: =D17*E17 -> 0
F18: =D18*E18 -> 0
F19: =D19*E19 -> 0
F20: =D20*E20 -> 0
F21: =D21*E21 -> 0
F22: =D22*E22 -> 0
F23: =D23*E23 -> 0
... F26: =D26*E26 -> 0
A28: 💡 IMPORTANTE: Quantidade Total = Nº de Fardos × Qtd por Fardo (calculado automaticamente se informar ambos)

Sheet CONSOLIDADO
A1: CONSOLIDADO - ATUALIZAÇÃO AUTOMÁTICA
A2: ⚡ AUTOMÁTICO! Preencha as abas Doces/Salgados/Bebidas e veja os produtos aparecerem aqui SEM linhas vazias!
A3: Categoria | B3: Nome do Produto | C3: Preço de compra (R$) | D3: Preço Unitário (R$) | E3: Nº de Fardos | F3: Qtd por Fardo | G3: Quantidade Total | H3: Estoque Mínimo
A4: =IF(Doces!A4="","","Doces") | B4: =IF(Doces!A4="","",Doces!A4) | C4: =IF(Doces!A4="","",Doces!B4) | D4: =IF(Doces!A4="","",Doces!C4) | E4: =IF(Doces!A4="","",Doces!D4) | F4: =IF(Doces!A4="","",Doces!E4) | G4: =IF(Doces!A4="","",Doces!F4) | H4: =IF(Doces!A4="","",Doces!G4)
A5: =IF(Doces!A5="","","Doces") | B5: =IF(Doces!A5="","",Doces!A5) | C5: =IF(Doces!A5="","",Doces!B5) | D5: =IF(Doces!A5="","",Doces!C5) | E5: =IF(Doces!A5="","",Doces!D5) | F5: =IF(Doces!A5="","",Doces!E5) | G5: =IF(Doces!A5="","",Doces!F5) | H5: =IF(Doces!A5="","",Doces!G5)
A6: =IF(Doces!A6="","","Doces") | B6: =IF(Doces!A6="","",Doces!A6) | C6: =IF(Doces!A6="","",Doces!B6) | D6: =IF(Doces!A6="","",Doces!C6) | E6: =IF(Doces!A6="","",Doces!D6) | F6: =IF(Doces!A6="","",Doces!E6) | G6: =IF(Doces!A6="","",Doces!F6) | H6: =IF(Doces!A6="","",Doces!G6)
A7: =IF(Doces!A7="","","Doces") | B7: =IF(Doces!A7="","",Doces!A7) | C7: =IF(Doces!A7="","",Doces!B7) | D7: =IF(Doces!A7="","",Doces!C7) | E7: =IF(Doces!A7="","",Doces!D7) | F7: =IF(Doces!A7="","",Doces!E7) | G7: =IF(Doces!A7="","",Doces!F7) | H7: =IF(Doces!A7="","",Doces!G7)
A8: =IF(Doces!A8="","","Doces") | B8: =IF(Doces!A8="","",Doces!A8) | C8: =IF(Doces!A8="","",Doces!B8) | D8: =IF(Doces!A8="","",Doces!C8) | E8: =IF(Doces!A8="","",Doces!D8) | F8: =IF(Doces!A8="","",Doces!E8) | G8: =IF(Doces!A8="","",Doces!F8) | H8: =IF(Doces!A8="","",Doces!G8)
A9: =IF(Doces!A9="","","Doces") | B9: =IF(Doces!A9="","",Doces!A9) | C9: =IF(Doces!A9="","",Doces!B9) | D9: =IF(Doces!A9="","",Doces!C9) | E9: =IF(Doces!A9="","",Doces!D9) | F9: =IF(Doces!A9="","",Doces!E9) | G9: =IF(Doces!A9="","",Doces!F9) | H9: =IF(Doces!A9="","",Doces!G9)
A10: =IF(Doces!A10="","","Doces") | B10: =IF(Doces!A10="","",Doces!A10) | C10: =IF(Doces!A10="","",Doces!B10) | D10: =IF(Doces!A10="","",Doces!C10) | E10: =IF(Doces!A10="","",Doces!D10) | F10: =IF(Doces!A10="","",Doces!E10) | G10: =IF(Doces!A10="","",Doces!F10) | H10: =IF(Doces!A10="","",Doces!G10)
A11: =IF(Doces!A11="","","Doces") | B11: =IF(Doces!A11="","",Doces!A11) | C11: =IF(Doces!A11="","",Doces!B11) | D11: =IF(Doces!A11="","",Doces!C11) | E11: =IF(Doces!A11="","",Doces!D11) | F11: =IF(Doces!A11="","",Doces!E11) | G11: =IF(Doces!A11="","",Doces!F11) | H11: =IF(Doces!A11="","",Doces!G11)
A12: =IF(Doces!A12="","","Doces") | B12: =IF(Doces!A12="","",Doces!A12) | C12: =IF(Doces!A12="","",Doces!B12) | D12: =IF(Doces!A12="","",Doces!C12) | E12: =IF(Doces!A12="","",Doces!D12) | F12: =IF(Doces!A12="","",Doces!E12) | G12: =IF(Doces!A12="","",Doces!F12) | H12: =IF(Doces!A12="","",Doces!G12)
A13: =IF(Doces!A13="","","Doces") | B13: =IF(Doces!A13="","",Doces!A13) | C13: =IF(Doces!A13="","",Doces!B13) | D13: =IF(Doces!A13="","",Doces!C13) | E13: =IF(Doces!A13="","",Doces!D13) | F13: =IF(Doces!A13="","",Doces!E13) | G13: =IF(Doces!A13="","",Doces!F13) | H13: =IF(Doces!A13="","",Doces!G13)
A14: =IF(Doces!A14="","","Doces") | B14: =IF(Doces!A14="","",Doces!A14) | C14: =IF(Doces!A14="","",Doces!B14) | D14: =IF(Doces!A14="","",Doces!C14) | E14: =IF(Doces!A14="","",Doces!D14) | F14: =IF(Doces!A14="","",Doces!E14) | G14: =IF(Doces!A14="","",Doces!F14) | H14: =IF(Doces!A14="","",Doces!G14)
A15: =IF(Doces!A15="","","Doces") | B15: =IF(Doces!A15="","",Doces!A15) | C15: =IF(Doces!A15="","",Doces!B15) | D15: =IF(Doces!A15="","",Doces!C15) | E15: =IF(Doces!A15="","",Doces!D15) | F15: =IF(Doces!A15="","",Doces!E15) | G15: =IF(Doces!A15="","",Doces!F15) | H15: =IF(Doces!A15="","",Doces!G15)
... A23: =IF(Doces!A23="","","Doces") | B23: =IF(Doces!A23="","",Doces!A23) | C23: =IF(Doces!A23="","",Doces!B23) | D23: =IF(Doces!A23="","",Doces!C23) | E23: =IF(Doces!A23="","",Doces!D23) | F23: =IF(Doces!A23="","",Doces!E23) | G23: =IF(Doces!A23="","",Doces!F23) | H23: =IF(Doces!A23="","",Doces!G23)
A24: =IF(Salgados!A4="","","Salgados") | B24: =IF(Salgados!A4="","",Salgados!A4) | C24: =IF(Salgados!A4="","",Salgados!B4) | D24: =IF(Salgados!A4="","",Salgados!C4) | E24: =IF(Salgados!A4="","",Salgados!D4) | F24: =IF(Salgados!A4="","",Salgados!E4) | G24: =IF(Salgados!A4="","",Salgados!F4) | H24: =IF(Salgados!A4="","",Salgados!G4)
A25: =IF(Salgados!A5="","","Salgados") | B25: =IF(Salgados!A5="","",Salgados!A5) | C25: =IF(Salgados!A5="","",Salgados!B5) | D25: =IF(Salgados!A5="","",Salgados!C5) | E25: =IF(Salgados!A5="","",Salgados!D5) | F25: =IF(Salgados!A5="","",Salgados!E5) | G25: =IF(Salgados!A5="","",Salgados!F5) | H25: =IF(Salgados!A5="","",Salgados!G5)
A26: =IF(Salgados!A6="","","Salgados") | B26: =IF(Salgados!A6="","",Salgados!A6) | C26: =IF(Salgados!A6="","",Salgados!B6) | D26: =IF(Salgados!A6="","",Salgados!C6) | E26: =IF(Salgados!A6="","",Salgados!D6) | F26: =IF(Salgados!A6="","",Salgados!E6) | G26: =IF(Salgados!A6="","",Salgados!F6) | H26: =IF(Salgados!A6="","",Salgados!G6)
A27: =IF(Salgados!A7="","","Salgados") | B27: =IF(Salgados!A7="","",Salgados!A7) | C27: =IF(Salgados!A7="","",Salgados!B7) | D27: =IF(Salgados!A7="","",Salgados!C7) | E27: =IF(Salgados!A7="","",Salgados!D7) | F27: =IF(Salgados!A7="","",Salgados!E7) | G27: =IF(Salgados!A7="","",Salgados!F7) | H27: =IF(Salgados!A7="","",Salgados!G7)
A28: =IF(Salgados!A8="","","Salgados") | B28: =IF(Salgados!A8="","",Salgados!A8) | C28: =IF(Salgados!A8="","",Salgados!B8) | D28: =IF(Salgados!A8="","",Salgados!C8) | E28: =IF(Salgados!A8="","",Salgados!D8) | F28: =IF(Salgados!A8="","",Salgados!E8) | G28: =IF(Salgados!A8="","",Salgados!F8) | H28: =IF(Salgados!A8="","",Salgados!G8)
A29: =IF(Salgados!A9="","","Salgados") | B29: =IF(Salgados!A9="","",Salgados!A9) | C29: =IF(Salgados!A9="","",Salgados!B9) | D29: =IF(Salgados!A9="","",Salgados!C9) | E29: =IF(Salgados!A9="","",Salgados!D9) | F29: =IF(Salgados!A9="","",Salgados!E9) | G29: =IF(Salgados!A9="","",Salgados!F9) | H29: =IF(Salgados!A9="","",Salgados!G9)
A30: =IF(Salgados!A10="","","Salgados") | B30: =IF(Salgados!A10="","",Salgados!A10) | C30: =IF(Salgados!A10="","",Salgados!B10) | D30: =IF(Salgados!A10="","",Salgados!C10) | E30: =IF(Salgados!A10="","",Salgados!D10) | F30: =IF(Salgados!A10="","",Salgados!E10) | G30: =IF(Salgados!A10="","",Salgados!F10) | H30: =IF(Salgados!A10="","",Salgados!G10)
A31: =IF(Salgados!A11="","","Salgados") | B31: =IF(Salgados!A11="","",Salgados!A11) | C31: =IF(Salgados!A11="","",Salgados!B11) | D31: =IF(Salgados!A11="","",Salgados!C11) | E31: =IF(Salgados!A11="","",Salgados!D11) | F31: =IF(Salgados!A11="","",Salgados!E11) | G31: =IF(Salgados!A11="","",Salgados!F11) | H31: =IF(Salgados!A11="","",Salgados!G11)
A32: =IF(Salgados!A12="","","Salgados") | B32: =IF(Salgados!A12="","",Salgados!A12) | C32: =IF(Salgados!A12="","",Salgados!B12) | D32: =IF(Salgados!A12="","",Salgados!C12) | E32: =IF(Salgados!A12="","",Salgados!D12) | F32: =IF(Salgados!A12="","",Salgados!E12) | G32: =IF(Salgados!A12="","",Salgados!F12) | H32: =IF(Salgados!A12="","",Salgados!G12)
A33: =IF(Salgados!A13="","","Salgados") | B33: =IF(Salgados!A13="","",Salgados!A13) | C33: =IF(Salgados!A13="","",Salgados!B13) | D33: =IF(Salgados!A13="","",Salgados!C13) | E33: =IF(Salgados!A13="","",Salgados!D13) | F33: =IF(Salgados!A13="","",Salgados!E13) | G33: =IF(Salgados!A13="","",Salgados!F13) | H33: =IF(Salgados!A13="","",Salgados!G13)
A34: =IF(Salgados!A14="","","Salgados") | B34: =IF(Salgados!A14="","",Salgados!A14) | C34: =IF(Salgados!A14="","",Salgados!B14) | D34: =IF(Salgados!A14="","",Salgados!C14) | E34: =IF(Salgados!A14="","",Salgados!D14) | F34: =IF(Salgados!A14="","",Salgados!E14) | G34: =IF(Salgados!A14="","",Salgados!F14) | H34: =IF(Salgados!A14="","",Salgados!G14)
A35: =IF(Salgados!A15="","","Salgados") | B35: =IF(Salgados!A15="","",Salgados!A15) | C35: =IF(Salgados!A15="","",Salgados!B15) | D35: =IF(Salgados!A15="","",Salgados!C15) | E35: =IF(Salgados!A15="","",Salgados!D15) | F35: =IF(Salgados!A15="","",Salgados!E15) | G35: =IF(Salgados!A15="","",Salgados!F15) | H35: =IF(Salgados!A15="","",Salgados!G15)
... A43: =IF(Salgados!A23="","","Salgados") | B43: =IF(Salgados!A23="","",Salgados!A23) | C43: =IF(Salgados!A23="","",Salgados!B23) | D43: =IF(Salgados!A23="","",Salgados!C23) | E43: =IF(Salgados!A23="","",Salgados!D23) | F43: =IF(Salgados!A23="","",Salgados!E23) | G43: =IF(Salgados!A23="","",Salgados!F23) | H43: =IF(Salgados!A23="","",Salgados!G23)
A44: =IF(Bebidas!A4="","","Bebidas") | B44: =IF(Bebidas!A4="","",Bebidas!A4) | C44: =IF(Bebidas!A4="","",Bebidas!B4) | D44: =IF(Bebidas!A4="","",Bebidas!C4) | E44: =IF(Bebidas!A4="","",Bebidas!D4) | F44: =IF(Bebidas!A4="","",Bebidas!E4) | G44: =IF(Bebidas!A4="","",Bebidas!F4) | H44: =IF(Bebidas!A4="","",Bebidas!G4)
A45: =IF(Bebidas!A5="","","Bebidas") | B45: =IF(Bebidas!A5="","",Bebidas!A5) | C45: =IF(Bebidas!A5="","",Bebidas!B5) | D45: =IF(Bebidas!A5="","",Bebidas!C5) | E45: =IF(Bebidas!A5="","",Bebidas!D5) | F45: =IF(Bebidas!A5="","",Bebidas!E5) | G45: =IF(Bebidas!A5="","",Bebidas!F5) | H45: =IF(Bebidas!A5="","",Bebidas!G5)
A46: =IF(Bebidas!A6="","","Bebidas") | B46: =IF(Bebidas!A6="","",Bebidas!A6) | C46: =IF(Bebidas!A6="","",Bebidas!B6) | D46: =IF(Bebidas!A6="","",Bebidas!C6) | E46: =IF(Bebidas!A6="","",Bebidas!D6) | F46: =IF(Bebidas!A6="","",Bebidas!E6) | G46: =IF(Bebidas!A6="","",Bebidas!F6) | H46: =IF(Bebidas!A6="","",Bebidas!G6)
A47: =IF(Bebidas!A7="","","Bebidas") | B47: =IF(Bebidas!A7="","",Bebidas!A7) | C47: =IF(Bebidas!A7="","",Bebidas!B7) | D47: =IF(Bebidas!A7="","",Bebidas!C7) | E47: =IF(Bebidas!A7="","",Bebidas!D7) | F47: =IF(Bebidas!A7="","",Bebidas!E7) | G47: =IF(Bebidas!A7="","",Bebidas!F7) | H47: =IF(Bebidas!A7="","",Bebidas!G7)
A48: =IF(Bebidas!A8="","","Bebidas") | B48: =IF(Bebidas!A8="","",Bebidas!A8) | C48: =IF(Bebidas!A8="","",Bebidas!B8) | D48: =IF(Bebidas!A8="","",Bebidas!C8) | E48: =IF(Bebidas!A8="","",Bebidas!D8) | F48: =IF(Bebidas!A8="","",Bebidas!E8) | G48: =IF(Bebidas!A8="","",Bebidas!F8) | H48: =IF(Bebidas!A8="","",Bebidas!G8)
A49: =IF(Bebidas!A9="","","Bebidas") | B49: =IF(Bebidas!A9="","",Bebidas!A9) | C49: =IF(Bebidas!A9="","",Bebidas!B9) | D49: =IF(Bebidas!A9="","",Bebidas!C9) | E49: =IF(Bebidas!A9="","",Bebidas!D9) | F49: =IF(Bebidas!A9="","",Bebidas!E9) | G49: =IF(Bebidas!A9="","",Bebidas!F9) | H49: =IF(Bebidas!A9="","",Bebidas!G9)
A50: =IF(Bebidas!A10="","","Bebidas") | B50: =IF(Bebidas!A10="","",Bebidas!A10) | C50: =IF(Bebidas!A10="","",Bebidas!B10) | D50: =IF(Bebidas!A10="","",Bebidas!C10) | E50: =IF(Bebidas!A10="","",Bebidas!D10) | F50: =IF(Bebidas!A10="","",Bebidas!E10) | G50: =IF(Bebidas!A10="","",Bebidas!F10) | H50: =IF(Bebidas!A10="","",Bebidas!G10)
A51: =IF(Bebidas!A11="","","Bebidas") | B51: =IF(Bebidas!A11="","",Bebidas!A11) | C51: =IF(Bebidas!A11="","",Bebidas!B11) | D51: =IF(Bebidas!A11="","",Bebidas!C11) | E51: =IF(Bebidas!A11="","",Bebidas!D11) | F51: =IF(Bebidas!A11="","",Bebidas!E11) | G51: =IF(Bebidas!A11="","",Bebidas!F11) | H51: =IF(Bebidas!A11="","",Bebidas!G11)
A52: =IF(Bebidas!A12="","","Bebidas") | B52: =IF(Bebidas!A12="","",Bebidas!A12) | C52: =IF(Bebidas!A12="","",Bebidas!B12) | D52: =IF(Bebidas!A12="","",Bebidas!C12) | E52: =IF(Bebidas!A12="","",Bebidas!D12) | F52: =IF(Bebidas!A12="","",Bebidas!E12) | G52: =IF(Bebidas!A12="","",Bebidas!F12) | H52: =IF(Bebidas!A12="","",Bebidas!G12)
A53: =IF(Bebidas!A13="","","Bebidas") | B53: =IF(Bebidas!A13="","",Bebidas!A13) | C53: =IF(Bebidas!A13="","",Bebidas!B13) | D53: =IF(Bebidas!A13="","",Bebidas!C13) | E53: =IF(Bebidas!A13="","",Bebidas!D13) | F53: =IF(Bebidas!A13="","",Bebidas!E13) | G53: =IF(Bebidas!A13="","",Bebidas!F13) | H53: =IF(Bebidas!A13="","",Bebidas!G13)
A54: =IF(Bebidas!A14="","","Bebidas") | B54: =IF(Bebidas!A14="","",Bebidas!A14) | C54: =IF(Bebidas!A14="","",Bebidas!B14) | D54: =IF(Bebidas!A14="","",Bebidas!C14) | E54: =IF(Bebidas!A14="","",Bebidas!D14) | F54: =IF(Bebidas!A14="","",Bebidas!E14) | G54: =IF(Bebidas!A14="","",Bebidas!F14) | H54: =IF(Bebidas!A14="","",Bebidas!G14)
...
